export const catchAsyncErrors = (theFunction) => {
  return (req, res, next) => {
    Promise.resolve(theFunction(req, res, next)).catch(next);
  };
};

//synchronous and ayncronous error ko btata h